Failure # 1 (occurred at 2021-08-18_17-27-47)
Traceback (most recent call last):
  File "/usr/local/lib/python3.6/dist-packages/ray/tune/trial_runner.py", line 739, in _process_trial
    results = self.trial_executor.fetch_result(trial)
  File "/usr/local/lib/python3.6/dist-packages/ray/tune/ray_trial_executor.py", line 729, in fetch_result
    result = ray.get(trial_future[0], timeout=DEFAULT_GET_TIMEOUT)
  File "/usr/local/lib/python3.6/dist-packages/ray/_private/client_mode_hook.py", line 82, in wrapper
    return func(*args, **kwargs)
  File "/usr/local/lib/python3.6/dist-packages/ray/worker.py", line 1564, in get
    raise value.as_instanceof_cause()
ray.exceptions.RayTaskError(PermissionError): [36mray::PPO.train()[39m (pid=8838, ip=172.17.0.2)
  File "python/ray/_raylet.pyx", line 534, in ray._raylet.execute_task
  File "python/ray/_raylet.pyx", line 484, in ray._raylet.execute_task.function_executor
  File "/usr/local/lib/python3.6/dist-packages/ray/_private/function_manager.py", line 563, in actor_method_executor
    return method(__ray_actor, *args, **kwargs)
  File "/usr/local/lib/python3.6/dist-packages/ray/rllib/agents/trainer.py", line 640, in train
    raise e
  File "/usr/local/lib/python3.6/dist-packages/ray/rllib/agents/trainer.py", line 629, in train
    result = Trainable.train(self)
  File "/usr/local/lib/python3.6/dist-packages/ray/tune/trainable.py", line 237, in train
    result = self.step()
  File "/usr/local/lib/python3.6/dist-packages/ray/rllib/agents/trainer_template.py", line 170, in step
    res = next(self.train_exec_impl)
  File "/usr/local/lib/python3.6/dist-packages/ray/util/iter.py", line 756, in __next__
    return next(self.built_iterator)
  File "/usr/local/lib/python3.6/dist-packages/ray/util/iter.py", line 783, in apply_foreach
    for item in it:
  File "/usr/local/lib/python3.6/dist-packages/ray/util/iter.py", line 783, in apply_foreach
    for item in it:
  File "/usr/local/lib/python3.6/dist-packages/ray/util/iter.py", line 843, in apply_filter
    for item in it:
  File "/usr/local/lib/python3.6/dist-packages/ray/util/iter.py", line 843, in apply_filter
    for item in it:
  File "/usr/local/lib/python3.6/dist-packages/ray/util/iter.py", line 783, in apply_foreach
    for item in it:
  File "/usr/local/lib/python3.6/dist-packages/ray/util/iter.py", line 783, in apply_foreach
    for item in it:
  File "/usr/local/lib/python3.6/dist-packages/ray/util/iter.py", line 783, in apply_foreach
    for item in it:
  [Previous line repeated 1 more time]
  File "/usr/local/lib/python3.6/dist-packages/ray/util/iter.py", line 876, in apply_flatten
    for item in it:
  File "/usr/local/lib/python3.6/dist-packages/ray/util/iter.py", line 828, in add_wait_hooks
    item = next(it)
  File "/usr/local/lib/python3.6/dist-packages/ray/util/iter.py", line 783, in apply_foreach
    for item in it:
  File "/usr/local/lib/python3.6/dist-packages/ray/util/iter.py", line 783, in apply_foreach
    for item in it:
  File "/usr/local/lib/python3.6/dist-packages/ray/util/iter.py", line 783, in apply_foreach
    for item in it:
  [Previous line repeated 1 more time]
  File "/usr/local/lib/python3.6/dist-packages/ray/util/iter.py", line 471, in base_iterator
    yield ray.get(futures, timeout=timeout)
  File "/usr/local/lib/python3.6/dist-packages/ray/_private/client_mode_hook.py", line 82, in wrapper
    return func(*args, **kwargs)
ray.exceptions.RayTaskError(PermissionError): [36mray::RolloutWorker.par_iter_next()[39m (pid=8801, ip=172.17.0.2)
  File "python/ray/_raylet.pyx", line 534, in ray._raylet.execute_task
  File "python/ray/_raylet.pyx", line 484, in ray._raylet.execute_task.function_executor
  File "/usr/local/lib/python3.6/dist-packages/ray/_private/function_manager.py", line 563, in actor_method_executor
    return method(__ray_actor, *args, **kwargs)
  File "/usr/local/lib/python3.6/dist-packages/ray/util/iter.py", line 1151, in par_iter_next
    return next(self.local_it)
  File "/usr/local/lib/python3.6/dist-packages/ray/rllib/evaluation/rollout_worker.py", line 339, in gen_rollouts
    yield self.sample()
  File "/usr/local/lib/python3.6/dist-packages/ray/rllib/evaluation/rollout_worker.py", line 740, in sample
    batches = [self.input_reader.next()]
  File "/usr/local/lib/python3.6/dist-packages/ray/rllib/evaluation/sampler.py", line 101, in next
    batches = [self.get_data()]
  File "/usr/local/lib/python3.6/dist-packages/ray/rllib/evaluation/sampler.py", line 231, in get_data
    item = next(self.rollout_provider)
  File "/usr/local/lib/python3.6/dist-packages/ray/rllib/evaluation/sampler.py", line 588, in _env_runner
    base_env.poll()
  File "/usr/local/lib/python3.6/dist-packages/ray/rllib/env/base_env.py", line 343, in poll
    self.new_obs = self.vector_env.vector_reset()
  File "/usr/local/lib/python3.6/dist-packages/ray/rllib/env/vector_env.py", line 161, in vector_reset
    return [e.reset() for e in self.envs]
  File "/usr/local/lib/python3.6/dist-packages/ray/rllib/env/vector_env.py", line 161, in <listcomp>
    return [e.reset() for e in self.envs]
  File "/usr/local/lib/python3.6/dist-packages/compiler_gym/wrappers/datasets.py", line 39, in reset
    return self.env.reset(benchmark=benchmark)
  File "/usr/local/lib/python3.6/dist-packages/gym/core.py", line 251, in reset
    return self.env.reset(**kwargs)
  File "/usr/local/lib/python3.6/dist-packages/compiler_gym/envs/llvm/llvm_env.py", line 295, in reset
    return super().reset(*args, **kwargs)
  File "/usr/local/lib/python3.6/dist-packages/compiler_gym/envs/compiler_env.py", line 709, in reset
    self.benchmark = benchmark
  File "/usr/local/lib/python3.6/dist-packages/compiler_gym/envs/compiler_env.py", line 420, in benchmark
    benchmark_object = self.datasets.benchmark(benchmark)
  File "/usr/local/lib/python3.6/dist-packages/compiler_gym/datasets/datasets.py", line 254, in benchmark
    return dataset.benchmark(uri)
  File "/usr/local/lib/python3.6/dist-packages/compiler_gym/envs/llvm/datasets/csmith.py", line 228, in benchmark
    return self.benchmark_from_seed(int(uri.split("/")[-1]))
  File "/usr/local/lib/python3.6/dist-packages/compiler_gym/envs/llvm/datasets/csmith.py", line 241, in benchmark_from_seed
    self.install()
  File "/usr/local/lib/python3.6/dist-packages/compiler_gym/envs/llvm/datasets/csmith.py", line 170, in install
    self._build_csmith(self.site_data_path, self.logger)
  File "/usr/local/lib/python3.6/dist-packages/compiler_gym/envs/llvm/datasets/csmith.py", line 200, in _build_csmith
    universal_newlines=True,
  File "/usr/lib/python3.6/subprocess.py", line 729, in __init__
    restore_signals, start_new_session)
  File "/usr/lib/python3.6/subprocess.py", line 1364, in _execute_child
    raise child_exception_type(errno_num, err_msg, err_filename)
PermissionError: [Errno 13] Permission denied: './configure'

